{"trial_id": "08", "hyperparameters": {"space": [{"class_name": "Int", "config": {"name": "fine_tune_at", "default": null, "conditions": [], "min_value": 50, "max_value": 100, "step": 10, "sampling": "linear"}}, {"class_name": "Choice", "config": {"name": "dense_units", "default": 256, "conditions": [], "values": [256, 512, 1024], "ordered": true}}, {"class_name": "Choice", "config": {"name": "dropout_rate", "default": 0.3, "conditions": [], "values": [0.3, 0.5, 0.6], "ordered": true}}, {"class_name": "Choice", "config": {"name": "learning_rate", "default": 0.0001, "conditions": [], "values": [0.0001, 0.001, 0.01], "ordered": true}}], "values": {"fine_tune_at": 80, "dense_units": 1024, "dropout_rate": 0.6, "learning_rate": 0.01}}, "metrics": {"metrics": {}}, "score": null, "best_step": 0, "status": "FAILED", "message": "Traceback (most recent call last):\n  File \"/Library/Frameworks/Python.framework/Versions/3.10/lib/python3.10/site-packages/keras_tuner/src/engine/base_tuner.py\", line 274, in _try_run_and_update_trial\n    self._run_and_update_trial(trial, *fit_args, **fit_kwargs)\n  File \"/Library/Frameworks/Python.framework/Versions/3.10/lib/python3.10/site-packages/keras_tuner/src/engine/base_tuner.py\", line 239, in _run_and_update_trial\n    results = self.run_trial(trial, *fit_args, **fit_kwargs)\n  File \"/Library/Frameworks/Python.framework/Versions/3.10/lib/python3.10/site-packages/keras_tuner/src/engine/tuner.py\", line 314, in run_trial\n    obj_value = self._build_and_fit_model(trial, *args, **copied_kwargs)\n  File \"/Library/Frameworks/Python.framework/Versions/3.10/lib/python3.10/site-packages/keras_tuner/src/engine/tuner.py\", line 233, in _build_and_fit_model\n    results = self.hypermodel.fit(hp, model, *args, **kwargs)\n  File \"/Library/Frameworks/Python.framework/Versions/3.10/lib/python3.10/site-packages/keras_tuner/src/engine/hypermodel.py\", line 149, in fit\n    return model.fit(*args, **kwargs)\n  File \"/Library/Frameworks/Python.framework/Versions/3.10/lib/python3.10/site-packages/keras/src/utils/traceback_utils.py\", line 122, in error_handler\n    raise e.with_traceback(filtered_tb) from None\n  File \"/Library/Frameworks/Python.framework/Versions/3.10/lib/python3.10/site-packages/keras_tuner/src/engine/tuner_utils.py\", line 76, in on_epoch_end\n    self._save_model()\n  File \"/Library/Frameworks/Python.framework/Versions/3.10/lib/python3.10/site-packages/keras_tuner/src/engine/tuner_utils.py\", line 86, in _save_model\n    self.model.save_weights(write_filepath)\n  File \"/Library/Frameworks/Python.framework/Versions/3.10/lib/python3.10/site-packages/h5py/_hl/group.py\", line 483, in __setitem__\n    ds = self.create_dataset(None, data=obj)\n  File \"/Library/Frameworks/Python.framework/Versions/3.10/lib/python3.10/site-packages/h5py/_hl/group.py\", line 183, in create_dataset\n    dsid = dataset.make_new_dset(group, shape, dtype, data, name, **kwds)\n  File \"/Library/Frameworks/Python.framework/Versions/3.10/lib/python3.10/site-packages/h5py/_hl/dataset.py\", line 168, in make_new_dset\n    dset_id.write(h5s.ALL, h5s.ALL, data)\n  File \"h5py/_objects.pyx\", line 54, in h5py._objects.with_phil.wrapper\n  File \"h5py/_objects.pyx\", line 55, in h5py._objects.with_phil.wrapper\n  File \"h5py/h5d.pyx\", line 281, in h5py.h5d.DatasetID.write\n  File \"h5py/_proxy.pyx\", line 115, in h5py._proxy.dset_rw\nOSError: [Errno 28] Can't write data (file write failed: time = Tue Nov 19 06:43:28 2024\n, filename = 'hyperparameter_search/xception_search/trial_08/checkpoint.weights.h5', file descriptor = 76, errno = 28, error message = 'No space left on device', buf = 0x10ed18000, total write size = 6291456, bytes this sub-write = 6291456, bytes actually written = 18446744073709551615, offset = 0)\n"}